# 异常

## 总结

异常是程序编译或运行过程中产生的，阻止当前方法或作用域继续执行的问题；可以使用**throw**关键字[抛出一个异常](#抛出异常)对象，异常也是一个对象，继承自**Object**基类，在堆中分配内存，如果一个方法想要在内部抛出非**RunTimeException**的异常，需要在定义方法时，使用**throws**关键字声明[异常说明](#异常说明)，可以只声明而不抛出，对于**RunTimeException**运行时异常，可以不做异常声明。异常声明在Java中饱受争议，可以利用异常链把其他类型的异常包装进RunTimeException来避开异常声明；抛出异常后，需要紧接着使用**catch**关键字[捕捉异常](#捕获异常)来做必要的处理，**catch**匹配特定的异常类型，可以通过[异常基类来匹配异常导出类](#捕获所有异常)，但导出的异常必须放在前面。捕获到异常后，异常信息储存在[栈轨迹](#栈轨迹)中，使用**printStackTrace()**方法打印栈轨迹，可以重定向到不同的流，也可以使用**getStackTrace()**方法获得栈轨迹的数组，处理完异常后，可以[重新抛出异常](#重新抛出异常),可以重新抛出捕捉到的这个异常，这时栈轨迹不会改变，也可以抛出新的异常，这时栈轨迹会以重新抛出点作为栈顶元素，之前的异常信息就会丢失，为了保存完整的异常信息，可以使用[异常链](#异常链)，从**Throwable**导出的**Exception**和**Error**以及从**Exception**导出的**RunTimeException**的构造器接受一个`cause`参数，用来表示原始异常，对于其他的异常对象，可以使用**initCause()**方法设置原始异常。最后，[finall](#finally)表示无论try块中是否抛出异常，都会被执行，甚至**break**和**continue**也不会阻碍finally执行。

[所有代码](#https://github.com/520MianXiangDuiXiang520/JAVA/tree/master/src/Note/exceptions)


## 概念

异常是程序中产生的**阻止当前方法或作用域**继续执行的问题

### 抛出异常

创建一个代表错误信息的**对象**，然后从当前环境中“抛出”以把错误信息传递到更大的环境中。

```java
if(t == null)
    throw new NullPointerException();
```

异常也是一个对象，需要使用`new`在**堆空间**为其分配内存，所有的标准异常类都有两个构造器——默认构造器和接受一个`String`的构造器，以便把相关信息放入异常对象

```java
if(t == null)
    throw new NullPointerException("t = null");
```

创建异常对象后，这个对象的引用就会被传递给`throw`

### 异常说明

Java鼓励人们把可能抛出的异常告知使用此方法的人，它使得调用者能确切的知道该怎样处理所有潜在异常，所以如果在方法中要抛出异常，需要在方法声明时使用`throws`关键字说明要抛出的异常，内部代码必须与异常说明保持一致，当然可以只声明异常而不抛出，为这个可能存在的异常占个位，这样在日后抛出异常时可以不用修改代码，常用在定义抽象类或接口时，派生类或接口的实现就可以抛出这些异常。

```java
package Note.exceptions;

class TooBig extends Exception{}
class TooSmall extends Exception{}

interface TestInterface1 {
    void method () throws TooBig, TooSmall;
    void method2();
}

public class ExceptionDescription implements TestInterface1 {
    @Override
    public void method() throws TooBig, TooSmall {
        throw new TooBig();
    }

    @Override
    public void method2(){
//        throw new TooSmall();
    }
}
```

### 捕获异常

* 监控区域：一段可能产生异常的代码，后面跟着处理这些异常的代码

如果在方法内部或作用域中抛出异常，这个方法或作用域将会在抛出异常的过程中结束，如果想阻止这种行为，需要将可能产生异常的代码放置在`try块`中以捕捉异常，异常处理程序必须紧跟在try块之后，以关键字`catch`表示，catch看似是一个仅接受一个异常类型的方法，并且必须要给这个“参数”一个标识符（e）虽然可以不用，但必须给出。

```java
try{
    //...
    // 可能产生TooBig异常
    //...
}catch(TooBig e){
    //异常处理
}
```

try,catch的结合似乎与switch与case的类似，但不同的是异常处理机制负责搜寻参数与异常类型相匹配的**第一个**处理程序，然后进入catch子句执行，而switch需要与每一个case匹配，所以我们才在每个case后面加上break；  

捕获异常时，异常会被第一个匹配的**catch**子句捕获，catch可以捕获由该异常导出的“子异常”，但如果在一开始就捕获基本异常，在后面再捕获导出异常是不允许的，应为后面的catch将永远无法被执行。

```java
package Note.exceptions;

class Annoyance extends Exception {}
class Sneeze extends Annoyance {}

public class Human {
    public static void main(String[] args) {
        try{
            throw new Sneeze();
        } catch(Sneeze s) {
            System.out.println("sneeze");
        } catch (Annoyance a) {
            System.out.println("annoyance");
        }

//        try {
//            throw new Sneeze();
//        } catch (Annoyance a) {
//            System.out.println("new Annoyance");
//        } catch (Sneeze s){
//            System.out.println(".....");
//        }
    }
}

```

捕捉异常之后，我们可以选择将它打印在控制台，但更让的选择是将错误信息发送到**标准错误流```**因为标准输出流`System.out`也许会被重定向。

### 恢复理论和终止理论

异常处理理论上有两种不同的模型，终止理论和恢复理论，恢复理论认为异常处理机制的主要作用是修正错误，产生异常后重新调用出现异常的方法，并认为第二次能成功；终止理论假设错误非常关键，一旦抛出，便无法挽回，也不能回来继续执行。

Java支持终止模型，如果想实现恢复模型，可以在遇到错误时调用方法修复错误而不是抛出异常，或者将try块放在while循环中，这样就会不断进入try块，直到获得满意的结果。

## 自定义异常

要定义自己的异常类，必须从已有的异常类中继承，编译器会为你添加默认的构造器，所以自定义异常几乎不用写多少代码，对于异常来说，最重要的部分是类名。

```java
class MyselfException extends Exception {}

public class SimpleException {
    public static void f() throws MyException {
        throw new MyException();
    }
    public static void main(String[] args) {
        try{
            f();
        }catch (MyselfException e){
            // 标准错误流
            System.err.println(e);
        }
    }
}
```

### 捕获所有异常

通过捕捉异常的基类`Exception`可以实现捕捉所有异常，`Exception`只是与编程相关的所有异常的基类，不会包含太多的信息，不过可以调用其`getMessage()`和`getLocalMessage()`来获取错误的详细信息或用本地语言表示详细信息。`toString()`会返回对**Throwable**的简单描述。而`printStackTrace()`可以打印Throwable和throwable的调用栈轨迹，默认输出到标准错误流，也可以选择要输出的流。

```java
void printStackTrace();
void printStackTrace(PrintStream);
void printStackTrace(java.io.PrintWriter);
```

`Throwable fillInStackTrace()`用来记录对象内部栈帧的当前状态，在重新抛出异常时很有用

```java
package Note.exceptions;
import static junbao.tool.Print.*;

public class ExceptionMethods {
    public static void main(String[] args) {
        try{
            throw new Exception("My Exception");
        }catch(Exception e){
            System.out.println(e.getMessage());
            System.out.println(e.getLocalizedMessage());
            System.out.println(e);
            cout(e.getStackTrace());
            // 输出栈轨迹
            e.printStackTrace(System.out);
            // 默认标准错误流
            e.printStackTrace();
        }
    }
}

```

### 栈轨迹

**printStackTrace()**可以打印栈轨迹，栈轨迹也可以使用`getStackTrace()`方法获得，该方法会返回一个由栈轨迹中的元素所构成的数组，每个数组代表栈中的一**帧**，元素0就是栈顶元素，也就是调用序列中最后一个方法的调用（也就是异常被创建和抛出的地方）最后一个栈底元素也就是调用序列中第一个方法的调用。

```java
package Note.exceptions;
import static junbao.tool.Print.*;

public class StackTraceDemo {
    public void q() throws MyException{
        throw new MyException();
    }

    public void w() throws MyException {
        q();
    }

    public void e() throws MyException {
        w();
    }

    public void r() throws MyException {
        e();
    }

    public static void main(String[] args) {
        StackTraceDemo stackTraceDemo = new StackTraceDemo();
        try{
            stackTraceDemo.r();
        }catch(MyException e){
            // 打印数组
            cout(e.getStackTrace(),"\n");
        }
    }
}
/*
Note.exceptions.StackTraceDemo.q(StackTraceDemo.java:6)
Note.exceptions.StackTraceDemo.w(StackTraceDemo.java:10)
Note.exceptions.StackTraceDemo.e(StackTraceDemo.java:14)
Note.exceptions.StackTraceDemo.r(StackTraceDemo.java:18)
Note.exceptions.StackTraceDemo.main(StackTraceDemo.java:24)
 */

```

### 重新抛出异常

有时候，在捕捉异常后，经过一系列操作，还需要重新抛出异常，尤其是使用Exception捕捉所有异常后，我们已经得到了异常的引用，可以直接抛出

```java
catch(Exception e){
    // .....
    throw e;
}
```

重抛异常会被抛给上一级环境的异常处理程序，同一个try块后面的catch语句就会被忽略（否则就会造成死循环），此外，这个异常对象的所有信息都会被保留，所以在高一级捕获此异常会获得这个异常的所有信息

```java
package Note.exceptions;
import static junbao.tool.Print.*;

public class Rethrowing {
    public static void f() throws Exception {
        System.out.println("originating the exception in f()");
        throw new Exception("thrown from f()");
    }
    public static void g() throws Exception {
        try{
            f();
        }catch(Exception e){
            System.out.println("Inside g() e.printStackTrace()");
            e.printStackTrace(System.out);
            throw e;  // 重新抛出异常
        }
    }

    public static void main(String[] args) {
        try{
            g();
        }catch(Exception e){
            System.out.println("g() main() printStackTrace()");
            cout(e.getStackTrace(),"\n");
        }
    }
}
/*
originating the exception in f()
Inside g() e.printStackTrace()
java.lang.Exception: thrown from f()
	at Note.exceptions.Rethrowing.f(Rethrowing.java:7)
	at Note.exceptions.Rethrowing.g(Rethrowing.java:11)
	at Note.exceptions.Rethrowing.main(Rethrowing.java:31)
g() main() printStackTrace()
Note.exceptions.Rethrowing.f(Rethrowing.java:7)
Note.exceptions.Rethrowing.g(Rethrowing.java:11)
Note.exceptions.Rethrowing.main(Rethrowing.java:31)

Process finished with exit code 0

 */

 // 栈轨迹依旧是 [f(), g(), main()], 说明异常的信息被完全保留

```

但这样做，只能得到原来抛出异常的地点的信息，重新抛出异常点的信息就无法更新，想要更新重新抛出异常点信息，需要使用`fillInStackTrace()`它通过把当前调用栈信息填入原来的异常对象而建立的，将返回一个Throwable对象。

```java
package Note.exceptions;
import static junbao.tool.Print.*;

public class Rethrowing {
    public static void f() throws Exception {
        System.out.println("originating the exception in f()");
        throw new Exception("thrown from f()");
    }
    public static void g() throws Exception {
        try{
            f();
        }catch(Exception e){
            System.out.println("Inside g() e.printStackTrace()");
            e.printStackTrace(System.out);
            throw e;  // 重新抛出异常
        }
    }

    public static void h() throws Exception {
        try{
            f();
        }catch(Exception e){
            System.out.println("Inside h() e.printStackTrace()");
            e.printStackTrace(System.out);
            throw (Exception)e.fillInStackTrace();
        }
    }

    public static void main(String[] args) {
        try{
            g();
        }catch(Exception e){
            System.out.println("g() main() printStackTrace()");
            cout(e.getStackTrace(),"\n");
        }
        try{
            h();
        }catch(Exception e){
            System.out.println("h () main() printStackTrace()");
            cout(e.getStackTrace(),"\n");
        }
    }
}
/*
originating the exception in f()
Inside g() e.printStackTrace()
java.lang.Exception: thrown from f()
	at Note.exceptions.Rethrowing.f(Rethrowing.java:7)
	at Note.exceptions.Rethrowing.g(Rethrowing.java:11)
	at Note.exceptions.Rethrowing.main(Rethrowing.java:31)
g() main() printStackTrace()
Note.exceptions.Rethrowing.f(Rethrowing.java:7)
Note.exceptions.Rethrowing.g(Rethrowing.java:11)
Note.exceptions.Rethrowing.main(Rethrowing.java:31)

originating the exception in f()
Inside h() e.printStackTrace()
java.lang.Exception: thrown from f()
	at Note.exceptions.Rethrowing.f(Rethrowing.java:7)
	at Note.exceptions.Rethrowing.h(Rethrowing.java:21)
	at Note.exceptions.Rethrowing.main(Rethrowing.java:37)
h () main() printStackTrace()
Note.exceptions.Rethrowing.h(Rethrowing.java:25)
Note.exceptions.Rethrowing.main(Rethrowing.java:37)


Process finished with exit code 0

 */

 // 最后的栈轨迹为[h(), main()]栈顶元素为重新抛出异常的方法

```

当然，又可能在捕获异常之后抛出另一个异常，这样，原来产生异常的发生点信息将会丢失，栈轨迹栈顶元素将变为新的异常发生点信息，类似于使用了**fillInStackTrace**


### 异常链


如果希望在捕捉一个异常后，抛出另一个异常，还想保留原来的异常信息，这就是**异常链**，**Throwable**的子类中，有三个基本异常类（**Exception**，**Error**,**RunTimeException**）的构造器接受一个`cause`参数，用来表示原始异常，这样就可以把原视异常传递给新异常，即便重新抛出新异常，也可以根据异常链追踪到原始异常。

```java
try{
    // ....
}catch(MyException e){
    throw RunTimeException(e);
}
```

对于其他异常，如果想要把异常链接起来，需要使用`initCause()`方法

```java
try{
    // .....
}catch(MyException e){
    NullPointerException npe = new NullPointerException();
    npe.initCause(e);
    throw npe;
}
```

## Java标准异常

**Throwable**用来表示任何可以被作为异常抛出的类，由这个基类导出两个类**Error**和**Exception**，**Error**表示编译时和系统错误，一般不用关心，**Exception**是可以被抛出的基本异常，Java类库，用户定义的方法，或者运行时故障都可能抛出Exception异常。Exception类的导出类中有一个特殊的类**RunTimeException**，他是运行时异常，会自动被Java虚拟机抛出，也不需要在异常说明中列出，故也被称为“不受检查异常”，不捕获这些异常，他们会直达main方法,在程序退出前，调用**printStackTrace()**并被报告给标准错误流。

```java
package Note.exceptions;

public class NeverCaught {
    static void f(){
        throw new RuntimeException();
    }

    static void g(){
        f();
    }

    public static void main(String[] args) {
        g();
    }
}

```

## finally

无论try块中的异常是否抛出，finally块中的语句总会被执行，常被用在把除内除之外的资源恢复到初始状态时，如打开的文件或网络连接，屏幕上画的图形，甚至是外部世界的某个开关。当涉及到**break**和**continue**时，**finally**仍然会执行。并且，应为**finally**总是执行，所以一个方法中有多个**return**无关紧要，重要的清理工作依旧会执行。

```java
package Note.exceptions;

public class MultipleReturns {
    public static void f(int i) {
        System.out.println("Initialization that requires cleanup");
        try{
            System.out.println("print 1");
            if(i == 1)
                return;
            System.out.println("print 2");
            if(i == 2)
                return;
            System.out.println("print 3");
            if(i == 3)
                return;
            System.out.println("end");
            return;
        }finally {
            System.out.println("finally");
        }
    }

    public static void main(String[] args) {
        for(int i = 1; i <= 4; i++ ){
            f(i);
        }
    }
}
/*
Initialization that requires cleanup
print 1
finally
Initialization that requires cleanup
print 1
print 2
finally
Initialization that requires cleanup
print 1
print 2
print 3
finally
Initialization that requires cleanup
print 1
print 2
print 3
end
finally

*/
```

但是通过某些方法使用**finally**可能导致异常的丢失，如

```java
try{
    throw new RunTimeException();
}finally{
    return;
}
```

## 异常限制

```java
package Note.exceptions;
import static junbao.tool.Print.*;

class BaseballException extends Exception {}
class Foul extends BaseballException {}
class Strike extends BaseballException {}

abstract class Inning {
    public Inning() throws BaseballException {}
    public void event() throws BaseballException {}
    public abstract void atBat() throws Strike, Foul;
    public void walk() {}
}

class StormException extends Exception {}
class RaineOut extends StormException {}
class PopFoul extends Foul {}

interface Storm {
    public void event() throws RaineOut;
    public void rainHard() throws RaineOut;
}

public class StormyInning extends Inning implements Storm {
    public StormyInning() throws BaseballException, RaineOut {}

    public StormyInning(String s) throws Foul, BaseballException {}

    @Override
    public void event(){

    }

    @Override
    public void atBat() throws PopFoul {

    }

    @Override
    public void rainHard() throws RaineOut {

    }

    // 不能通过编译，因为基类的walk()没有异常说明
    // public void walk() throws RaineOut{}
}

```

* 异常限制对构造器不起作用，但派生类构造器的异常说明必须包含基类构造器的异常说明
* 派生类方法可以不抛出任何异常
* 异常说明不能作为重载的依据

## 构造器中的异常

如打开一个文件，这样的动作只有在对象使用完毕，并且用户调用了特殊的方法才会被清理，如果在构造器内部抛出异常，那么这些清理行为也许就不能正常工作了，使用**finally**并不能完全解决这个问题，因为如果构造器半途而废，那对象的某些部分可能还没有被创建，而这些部分在**finally**中每次都要执行清理，对此，最安全的办法是使用嵌套**try**子句。

[InputFile.java](https://github.com/520MianXiangDuiXiang520/JAVA/blob/master/src/Note/exceptions/InputFile.java)  
[Cleanup.java](https://github.com/520MianXiangDuiXiang520/JAVA/blob/master/src/Note/exceptions/Cleanup.java)
